Workbook

Sheet Concept-summary
B1: Topic_tag अधिकरण-स्तरे | C1: Commentary_tag व्याख्यान-स्तरे | D1: Gist_tag तात्पर्य-स्तरे | E1: Concept_tag विषय-स्तरे | F1: Treatise_tag ग्रन्थ-स्तरे | G1: Relation_tag पदार्थ-संबन्धः
A2: - | B2: =CONCATENATE('Concept-detail'!F3) -> उत्तरपक्षः rebuttal | C2: =CONCATENATE('Concept-detail'!F17) -> फलम् purpose | D2: =CONCATENATE('Concept-detail'!F24) -> अपवर्गः exception | E2: =CONCATENATE('Concept-detail'!F34) -> निरूप्य - निरूपक-भावः statement - proof | F2: =CONCATENATE('Concept-detail'!F38) -> नियाम्य - नियामक-भावः | G2: =CONCATENATE('Concept-detail'!F86) -> अर्थापत्तिः implied meaning
A3: अतिक्रान्तावेक्षणम् retrospection | B3: =CONCATENATE('Concept-detail'!F4) -> प्रसङ्गः-सङ्गतिः context | C3: =CONCATENATE('Concept-detail'!F18) -> अर्थवादः description | D3: =CONCATENATE('Concept-detail'!F25) -> उत्तरपक्षः Refutation | E3: =CONCATENATE('Concept-detail'!F35) -> धर्म - धर्मि-भावः property - holder | F3: =CONCATENATE('Concept-detail'!F39) -> प्रतिपाद्य - प्रतिपादक-भावः | G3: =CONCATENATE('Concept-detail'!F87) -> उद्देशः concise summary
A4: अतिदेशः extrapolation | B4: =CONCATENATE('Concept-detail'!F5) -> हेतुता-सङ्गतिः argumentation | C4: =CONCATENATE('Concept-detail'!F19) -> उपपत्तिः cogency | D4: =CONCATENATE('Concept-detail'!F26) -> उपमानम् analogy | E4: =CONCATENATE('Concept-detail'!F36) -> अवच्छेद्य - अवच्छेद्यक-भावः | F4: =CONCATENATE('Concept-detail'!F40) -> आधार - आधेय-भावः | G4: =CONCATENATE('Concept-detail'!F88) -> संशयः Doubt
A5: अधिकरणम् Topic | B5: =CONCATENATE('Concept-detail'!F6) -> अवसरः-सङ्गतिः scope | C5: =CONCATENATE('Concept-detail'!F20) -> अधिकाारी-विषय-संबन्धः the qualified student and the theme-relation | D5: =CONCATENATE('Concept-detail'!F27) -> पूर्वपक्षः prima facie argument | F5: =CONCATENATE('Concept-detail'!F41) -> कार्य - कारण-भावः effect - cause | G5: =CONCATENATE('Concept-detail'!F89) -> स्वसंज्ञा technical term
A6: अनागतावेक्षणम् forward reference | B6: =CONCATENATE('Concept-detail'!F7) -> निर्वाहकैक्य-सङ्गतिः oneness performing | C6: =CONCATENATE('Concept-detail'!F21) -> विषयः-प्रयोजन-संबन्धः the theme and result-relation | D6: =CONCATENATE('Concept-detail'!F28) -> प्रदेशः partial mention to prove | F6: =CONCATENATE('Concept-detail'!F42) -> नियोज्य - नियोजक-भावः | G6: =CONCATENATE('Concept-detail'!F90) -> सम्भवः possibility
A7: अनुमतम् agreement | B7: =CONCATENATE('Concept-detail'!F8) -> कार्यैक्यम् (एकफलकत्वम्)-सङ्गतिः oneness result | C7: =CONCATENATE('Concept-detail'!F22) -> अधिकारी-प्रयोजन-संबन्धः the qualified student and result-relation | D7: =CONCATENATE('Concept-detail'!F29) -> प्रसङ्गः Repetition | F7: =CONCATENATE('Concept-detail'!F43) -> प्रकार - प्रकारि-भावः | G7: =CONCATENATE('Concept-detail'!F91) -> पदच्छेदः division of words
A8: अपदेशः/हेत्वर्थः reason | B8: =CONCATENATE('Concept-detail'!F9) -> दृष्टान्तः-सङ्गतिः exemplification | D8: =CONCATENATE('Concept-detail'!F30) -> वाक्यशेषः filling implied words | F8: =CONCATENATE('Concept-detail'!F44) -> प्रतियोगि - अनुयोगि-भावः | G8: =CONCATENATE('Concept-detail'!F92) -> पदार्थोक्तिः meaning of words
A9: अपवर्गः exception | B9: =CONCATENATE('Concept-detail'!F10) -> प्रत्युदाहरणम्-सङ्गतिः re-answer | G9: =CONCATENATE('Concept-detail'!F93) -> विग्रहः analysis of grammatical complexes
A10: अर्थापत्तिः implied meaning | B10: =CONCATENATE('Concept-detail'!F11) -> आक्षेपः-सङ्गतिः objection | G10: =CONCATENATE('Concept-detail'!F94) -> वाक्ययोजना prose-rendering
A11: उत्तरपक्षः Refutation | B11: =CONCATENATE('Concept-detail'!F12) -> आक्षेपः objection | G11: =CONCATENATE('Concept-detail'!F95) -> अतिक्रान्तावेक्षणम् retrospection
A12: उद्देशः concise summary | B12: =CONCATENATE('Concept-detail'!F13) -> समाधानम् answer | G12: =CONCATENATE('Concept-detail'!F96) -> अनागतावेक्षणम् forward reference
A13: उपदेशः advisory guidance | B13: =CONCATENATE('Concept-detail'!F14) -> उपसंहारः conclusion | G13: =CONCATENATE('Concept-detail'!F97) -> अनुमतम् agreement
A14: उपमानम् analogy | B14: =CONCATENATE('Concept-detail'!F15) -> अभ्यासः repetition | G14: =CONCATENATE('Concept-detail'!F98) -> अपदेशः/हेत्वर्थः reason
A15: ऊह्यम् deduction | G15: =CONCATENATE('Concept-detail'!F99) -> उपदेशः advisory guidance
A16: एकान्तः exclusive statement | G16: =CONCATENATE('Concept-detail'!F100) -> ऊह्यम् deduction
A17: निदर्शनम्/दृष्टान्तः example | G17: =CONCATENATE('Concept-detail'!F101) -> एकान्तः exclusive statement
A18: नियोगः Dictate | G18: =CONCATENATE('Concept-detail'!F102) -> निदर्शनम्/दृष्टान्तः example
A19: निर्णयः conclusion | G19: =CONCATENATE('Concept-detail'!F103) -> नियोगः Dictate
A20: निर्देशः detailed enumeration of uddesha | G20: =CONCATENATE('Concept-detail'!F104) -> निर्णयः conclusion
A21: निर्वचनम् etymology | G21: =CONCATENATE('Concept-detail'!F105) -> निर्देशः detailed enumeration of uddesha
A22: पदार्थः Term definition | G22: =CONCATENATE('Concept-detail'!F106) -> निर्वचनम् etymology
A23: पूर्वपक्षः prima facie argument | G23: =CONCATENATE('Concept-detail'!F107) -> पदार्थः Term definition
A24: प्रदेशः partial mention to prove | G24: =CONCATENATE('Concept-detail'!F108) -> योगः connecting
A25: प्रसङ्गः Repetition | G25: =CONCATENATE('Concept-detail'!F109) -> विकल्पः alternative
A26: योगः connecting | G26: =CONCATENATE('Concept-detail'!F110) -> विपर्ययः contrariety
... A38: सम्भवः possibility | G38: =CONCATENATE('Concept-detail'!F122) -> -

Sheet Sheet15

Sheet Concept-detail
A1: Tag_type_dv | B1: Tag_type | C1: Tag_target | D1: Tag_dv | E1: Tag_en English meaning | F1: tag User-visible tag | G1: vakya_tag | H1: sambandha_tag | I1: desc_dv लक्षणम् | J1: desc_en | K1: example उदाहरणम्
A2: अधिकरण | B2: Topic | C2: Sambandha | D2: पूर्वपक्षः | E2: adversary argument | F2: =CONCATENATE(D2, " ", E2) -> पूर्वपक्षः adversary argument | H2: =CONCATENATE(D2, " ", E2) -> पूर्वपक्षः adversary argument
A3: अधिकरण | B3: Topic | C3: Sambandha | D3: उत्तरपक्षः | E3: rebuttal | F3: =CONCATENATE(D3, " ", E3) -> उत्तरपक्षः rebuttal | H3: =CONCATENATE(D3, " ", E3) -> उत्तरपक्षः rebuttal
A4: अधिकरण | B4: Topic | C4: Sambandha | D4: प्रसङ्गः-सङ्गतिः | E4: context | F4: =CONCATENATE(D4, " ", E4) -> प्रसङ्गः-सङ्गतिः context | H4: =CONCATENATE(D4, " ", E4) -> प्रसङ्गः-सङ्गतिः context
A5: अधिकरण | B5: Topic | C5: Sambandha | D5: हेतुता-सङ्गतिः | E5: argumentation | F5: =CONCATENATE(D5, " ", E5) -> हेतुता-सङ्गतिः argumentation | H5: =CONCATENATE(D5, " ", E5) -> हेतुता-सङ्गतिः argumentation
A6: अधिकरण | B6: Topic | C6: Sambandha | D6: अवसरः-सङ्गतिः | E6: scope | F6: =CONCATENATE(D6, " ", E6) -> अवसरः-सङ्गतिः scope | H6: =CONCATENATE(D6, " ", E6) -> अवसरः-सङ्गतिः scope
A7: अधिकरण | B7: Topic | C7: Sambandha | D7: निर्वाहकैक्य-सङ्गतिः | E7: oneness performing | F7: =CONCATENATE(D7, " ", E7) -> निर्वाहकैक्य-सङ्गतिः oneness performing | H7: =CONCATENATE(D7, " ", E7) -> निर्वाहकैक्य-सङ्गतिः oneness performing
A8: अधिकरण | B8: Topic | C8: Sambandha | D8: कार्यैक्यम् (एकफलकत्वम्)-सङ्गतिः | E8: oneness result | F8: =CONCATENATE(D8, " ", E8) -> कार्यैक्यम् (एकफलकत्वम्)-सङ्गतिः oneness result | H8: =CONCATENATE(D8, " ", E8) -> कार्यैक्यम् (एकफलकत्वम्)-सङ्गतिः oneness result
A9: अधिकरण | B9: Topic | C9: Sambandha | D9: दृष्टान्तः-सङ्गतिः | E9: exemplification | F9: =CONCATENATE(D9, " ", E9) -> दृष्टान्तः-सङ्गतिः exemplification | H9: =CONCATENATE(D9, " ", E9) -> दृष्टान्तः-सङ्गतिः exemplification
A10: अधिकरण | B10: Topic | C10: Sambandha | D10: प्रत्युदाहरणम्-सङ्गतिः | E10: re-answer | F10: =CONCATENATE(D10, " ", E10) -> प्रत्युदाहरणम्-सङ्गतिः re-answer | H10: =CONCATENATE(D10, " ", E10) -> प्रत्युदाहरणम्-सङ्गतिः re-answer
A11: अधिकरण | B11: Topic | C11: Sambandha | D11: आक्षेपः-सङ्गतिः | E11: objection | F11: =CONCATENATE(D11, " ", E11) -> आक्षेपः-सङ्गतिः objection | H11: =CONCATENATE(D11, " ", E11) -> आक्षेपः-सङ्गतिः objection
A12: व्याख्यान | B12: Commentary | C12: Sambandha | D12: आक्षेपः | E12: objection | F12: =CONCATENATE(D12, " ", E12) -> आक्षेपः objection | H12: =CONCATENATE(, " ", F12) -> आक्षेपः objection
A13: व्याख्यान | B13: Commentary | C13: Sambandha | D13: समाधानम् | E13: answer | F13: =CONCATENATE(D13, " ", E13) -> समाधानम् answer | H13: =CONCATENATE(, " ", F13) -> समाधानम् answer
A14: तात्पर्य | B14: Gist | C14: Sambandha | D14: उपसंहारः | E14: conclusion | F14: =CONCATENATE(D14, " ", E14) -> उपसंहारः conclusion | G14: =CONCATENATE(, " ", F14) -> उपसंहारः conclusion | H14: =CONCATENATE(, " ", F14) -> उपसंहारः conclusion
A15: तात्पर्य | B15: Gist | C15: Sambandha | D15: अभ्यासः | E15: repetition | F15: =CONCATENATE(D15, " ", E15) -> अभ्यासः repetition | H15: =CONCATENATE(, " ", F15) -> अभ्यासः repetition
A16: तात्पर्य | B16: Gist | C16: Sambandha | D16: अपूर्वता | E16: novelty | F16: =CONCATENATE(D16, " ", E16) -> अपूर्वता novelty | H16: =CONCATENATE(, " ", F16) -> अपूर्वता novelty
A17: तात्पर्य | B17: Gist | C17: Sambandha | D17: फलम् | E17: purpose | F17: =CONCATENATE(D17, " ", E17) -> फलम् purpose | H17: =CONCATENATE(, " ", F17) -> फलम् purpose
A18: तात्पर्य | B18: Gist | C18: Sambandha | D18: अर्थवादः | E18: description | F18: =CONCATENATE(D18, " ", E18) -> अर्थवादः description | H18: =CONCATENATE(, " ", F18) -> अर्थवादः description
A19: तात्पर्य | B19: Gist | C19: Sambandha | D19: उपपत्तिः | E19: cogency | F19: =CONCATENATE(D19, " ", E19) -> उपपत्तिः cogency | H19: =CONCATENATE(, " ", F19) -> उपपत्तिः cogency
A20: ग्रन्थ | B20: Treatise | C20: Sambandha | D20: अधिकाारी-विषय-संबन्धः | E20: the qualified student and the theme-relation | F20: =CONCATENATE(D20, " ", E20) -> अधिकाारी-विषय-संबन्धः the qualified student and the theme-relation | H20: =CONCATENATE(, " ", F20) -> अधिकाारी-विषय-संबन्धः the qualified student and the theme-relation
A21: ग्रन्थ | B21: Treatise | C21: Sambandha | D21: विषयः-प्रयोजन-संबन्धः | E21: the theme and result-relation | F21: =CONCATENATE(D21, " ", E21) -> विषयः-प्रयोजन-संबन्धः the theme and result-relation | H21: =CONCATENATE(, " ", F21) -> विषयः-प्रयोजन-संबन्धः the theme and result-relation
A22: ग्रन्थ | B22: Treatise | C22: Sambandha | D22: अधिकारी-प्रयोजन-संबन्धः | E22: the qualified student and result-relation | F22: =CONCATENATE(D22, " ", E22) -> अधिकारी-प्रयोजन-संबन्धः the qualified student and result-relation | H22: =CONCATENATE(, " ", F22) -> अधिकारी-प्रयोजन-संबन्धः the qualified student and result-relation
A23: ग्रन्थ | B23: Treatise | C23: Sambandha | D23: अधिकारी-विषय-प्रयोजन-संबन्धः | E23: the qualified student, the theme and result-relation | F23: =CONCATENATE(D23, " ", E23) -> अधिकारी-विषय-प्रयोजन-संबन्धः the qualified student, the theme and result-relation | H23: =CONCATENATE(, " ", F23) -> अधिकारी-विषय-प्रयोजन-संबन्धः the qualified student, the theme and result-relation
A24: तन्त्रयुक्ति | B24: Tantrayukti | C24: Sambandha | D24: अपवर्गः | E24: exception | F24: =CONCATENATE(D24, " ", E24) -> अपवर्गः exception | H24: =CONCATENATE(, " ",F24) -> अपवर्गः exception | I24: अभिव्याप्य अपकर्षणम् अपवर्गः (कञ्चित् विधिम् उत्सर्गेण अभितः व्यापकं कृत्वा व्याप्यत्वेन अनिष्टात् विषयात् अपोहनम्) | J24: The statement of an exception to a general rule. | K24: अस्वेद्या विषोपसृष्टाः, अन्यत्र कीटविषात् इति।
A25: तन्त्रयुक्ति | B25: Tantrayukti | C25: Sambandha | D25: उत्तरपक्षः | E25: Refutation | F25: =CONCATENATE(D25, " ", E25) -> उत्तरपक्षः Refutation | G25: =CONCATENATE(, " ",F25) -> उत्तरपक्षः Refutation | H25: =CONCATENATE(, " ",F25) -> उत्तरपक्षः Refutation | I25: तस्य निर्णयवाक्यम् | J25: Which refutes the पूर्वपक्ष | K25: प्रधानप्रत्ययार्थवचनमर्थस्यान्यप्रमाणत्वात्
A26: तन्त्रयुक्ति | B26: Tantrayukti | C26: Sambandha | D26: उपमानम् | E26: analogy | F26: =CONCATENATE(D26, " ", E26) -> उपमानम् analogy | H26: =CONCATENATE(, " ",F26) -> उपमानम् analogy | I26: दृष्टेन अदृष्टार्थस्य साधनम् | J26: To prove the unknown or less known with known or with an analogy. | K26: यथा शिखा मयूराणां नागानां मणयो यथा। तद्वद् वेदाङ्गशास्त्राणां गणितं मूर्धनि स्थितम्॥
A27: तन्त्रयुक्ति | B27: Tantrayukti | C27: Sambandha | D27: पूर्वपक्षः | E27: prima facie argument | F27: =CONCATENATE(D27, " ", E27) -> पूर्वपक्षः prima facie argument | G27: =CONCATENATE(, " ", F27) -> पूर्वपक्षः prima facie argument | H27: =CONCATENATE(, " ",F27) -> पूर्वपक्षः prima facie argument | I27: प्रतिषेद्धव्यं वाक्यम् | J27: A statement which needs to be refuted.
A28: तन्त्रयुक्ति | B28: Tantrayukti | C28: Sambandha | D28: प्रदेशः | E28: partial mention to prove | F28: =CONCATENATE(D28, " ", E28) -> प्रदेशः partial mention to prove | H28: =CONCATENATE(, " ",F28) -> प्रदेशः partial mention to prove | I28: वक्तव्येन साधनम् | J28: To prove the present subject with something that was stated/something to be stated later. | K28: सामदाानभेददण्डैर्वा यथापत्सु व्याख्यास्यामः।
A29: तन्त्रयुक्ति | B29: Tantrayukti | C29: Sambandha | D29: प्रसङ्गः | E29: Repetition | F29: =CONCATENATE(D29, " ", E29) -> प्रसङ्गः Repetition | H29: =CONCATENATE(, " ",F29) -> प्रसङ्गः Repetition | I29: पूर्वाभिहितस्य अर्थस्य केनचित् सम्बन्धान्तरेण पुनरभिधानम् | J29: To state or describe again, what has been stated or described earlier, in a different connction. | K29: कृषिकर्मप्रदिष्टायां भूमौ इति समानं पूर्वेण।
A30: तन्त्रयुक्ति | B30: Tantrayukti | C30: Sambandha | D30: वाक्यशेषः | E30: filling implied words | F30: =CONCATENATE(D30, " ", E30) -> वाक्यशेषः filling implied words | H30: =CONCATENATE(, " ",F30) -> वाक्यशेषः filling implied words | I30: येन पदेन अनुक्तेन वाक्यं समाप्यते | J30: To provide the unsaid word/s in order to complete the construction or the meaning of a sentence. | K30: ‘छिन्नपक्षस्येव राज्ञश्चेष्टानाशश्चेति’ तत्र शकुनेः इति वाक्यशेषः। यथा वा सुश्रुते शिरःपाणिपादपार्श्वपृष्ठोदरोरसाम् इत्युक्ते पुरुषग्रहणमिति गम्यते।
A31: तन्त्रयुक्ति | B31: Tantrayukti | C31: Sambandha | D31: विधानम् | E31: table of content | F31: =CONCATENATE(D31, " ", E31) -> विधानम् table of content | H31: =CONCATENATE(, " ",F31) -> विधानम् table of content | I31: शास्त्रस्य प्रकरणानुपूर्वी | J31: The table of contents of a scientific work | K31: विद्यासमुद्देशे वृद्धसंयोगः इन्द्रियजयः इत्यादि
A32: तन्त्रयुक्ति | B32: Tantrayukti | C32: Sambandha | D32: - | F32: - | G32: =CONCATENATE(D32, " ", E32) -> - | H32: =CONCATENATE(D32, " ", E32) -> -
A33: तन्त्रयुक्ति | B33: Tantrayukti | C33: Sambandha | D33: अधिकरणम् | E33: Topic | F33: अधिकरणम् - Topic | H33: अधिकरणम् - Topic
A34: सम्बन्ध | B34: Relation | C34: Sambandha | D34: निरूप्य - निरूपक-भावः | E34: statement - proof | F34: =CONCATENATE(D34, " ", E34) -> निरूप्य - निरूपक-भावः statement - proof | H34: =CONCATENATE(, " ", F34) -> निरूप्य - निरूपक-भावः statement - proof
A35: सम्बन्ध | B35: Relation | C35: Sambandha | D35: धर्म - धर्मि-भावः | E35: property - holder | F35: =CONCATENATE(D35, " ", E35) -> धर्म - धर्मि-भावः property - holder | H35: =CONCATENATE(, " ", F35) -> धर्म - धर्मि-भावः property - holder
A36: सम्बन्ध | B36: Relation | C36: Sambandha | D36: अवच्छेद्य - अवच्छेद्यक-भावः | F36: =CONCATENATE(D36, " ", E36) -> अवच्छेद्य - अवच्छेद्यक-भावः | H36: =CONCATENATE(, " ", F36) -> अवच्छेद्य - अवच्छेद्यक-भावः
A37: सम्बन्ध | B37: Relation | C37: Sambandha | D37: उपादान - उपादेय-भावः | F37: =CONCATENATE(D37, " ", E37) -> उपादान - उपादेय-भावः | H37: =CONCATENATE(, " ", F37) -> उपादान - उपादेय-भावः
A38: सम्बन्ध | B38: Relation | C38: Sambandha | D38: नियाम्य - नियामक-भावः | F38: =CONCATENATE(D38, " ", E38) -> नियाम्य - नियामक-भावः | H38: =CONCATENATE(, " ", F38) -> नियाम्य - नियामक-भावः
A39: सम्बन्ध | B39: Relation | C39: Sambandha | D39: प्रतिपाद्य - प्रतिपादक-भावः | F39: =CONCATENATE(D39, " ", E39) -> प्रतिपाद्य - प्रतिपादक-भावः | H39: =CONCATENATE(, " ", F39) -> प्रतिपाद्य - प्रतिपादक-भावः
A40: सम्बन्ध | B40: Relation | C40: Sambandha | D40: आधार - आधेय-भावः | F40: =CONCATENATE(D40, " ", E40) -> आधार - आधेय-भावः | H40: =CONCATENATE(, " ", F40) -> आधार - आधेय-भावः
...

Sheet Vakyas
A1: Vakya_id | B1: Vakya वाक्यम् | C1: Tantrayukti_tag वाक्य-स्तरे (तन्त्रयुक्तिः) | D1: Topic_tag अधिकरण-स्तरे | E1: Commentary_tag व्याख्यान-स्तरे | F1: Gist_tag तात्पर्य-स्तरे | G1: Concept_tag विषय-स्तरे | H1: Treatise_tag ग्रन्थ-स्तरे (अनुबन्ध-चतुष्टयम्) | I1: Notes
A2: 0 | B2: निधाय हृदि विश्वेशं विधाय गुरुवन्दनम् । बालानां सुखबोधाय क्रियते तर्कसंग्रहः ॥ | C2: प्रयोजनम् purpose | F2: उपक्रमः beginning | H2: प्रयोजनम् result | I2: अतिक्रान्तावेक्षणम् retrospection
A3: 1 | B3: द्रव्यगुणकर्मसामान्यविशेषसमवायाऽभावाः सप्तपदार्थाः ॥ १॥ | C3: - | F3: उपक्रमः beginning | I3: उद्देशः (लक्ष्यम्) illustration
A4: 2 | B4: तत्र द्रव्याणि पृथिव्यप्तेजोवाय्वाकाशाकालदिगात्ममनांसि नवैव ॥ २॥ | C4: निर्देशः detailed enumeration of uddesha | E4: - | I4: उद्देशः (लक्ष्यम्) illustration
A5: 3 | B5: रूप-रस-गन्ध-स्पर्श-संख्या-परिमाण-पृथक्त्व-संयोग-विभग-परत्वापरत्व-गुरुत्व-द्रवत्व-स्नेह-शब्द-बुद्धि-सुख-दुःखेच्छा-द्वेष-प्रयत्न-धर्माधर्म-संस्काराः चतुर्विंशतिर्गुणाः॥3॥ | C5: निर्देशः detailed enumeration of uddesha | E5: - | I5: उद्देशः (लक्ष्यम्) illustration
A6: 4 | B6: उत्क्षेपणापक्षेपणाकुञ्चनप्रसारणगमनानि पञ्च कर्माणि ॥ ४॥ | C6: निर्देशः detailed enumeration of uddesha | E6: - | I6: उद्देशः (लक्ष्यम्) illustration
A7: 5 | B7: परमपरं चेति द्विविधं सामान्यम् ॥ ५॥ | C7: निर्देशः detailed enumeration of uddesha | E7: - | I7: उद्देशः (लक्ष्यम्) illustration
A8: 6 | B8: नित्यद्रव्यवृत्तयो विशेषास्त्वनन्ता एव ॥ ६॥ | C8: निर्देशः detailed enumeration of uddesha | E8: - | I8: योगः connecting
A9: 7 | B9: समवायस्त्वेक एव ॥ ७॥ | C9: निर्देशः detailed enumeration of uddesha | E9: - | I9: योगः connecting
A10: 8 | B10: अभावश्चतुर्विधः प्रागभावः प्रध्वंसाभावःअत्यन्ताभावः अन्योन्याभावश्चेति ॥ ८॥ | C10: निर्देशः detailed enumeration of uddesha | E10: - | I10: उद्देशः (लक्ष्यम्) illustration
A11: 9 | B11: तत्र गन्धवती पृथिवी । | C11: पदार्थः Term definition | E11: - | I11: पदार्थः Term definition
A12: 10 | B12: सा द्विविधानित्याऽनित्या च ।! | C12: निर्देशः detailed enumeration of uddesha | E12: - | I12: योगः connecting
A13: 11 | B13: नित्या परमाणुरूपा । | C13: उद्देशः concise summary | E13: - | I13: पदार्थः Term definition
A14: 12 | B14: अनित्या कार्यरूपा । | C14: उद्देशः concise summary | E14: - | I14: पदार्थः Term definition
A15: 13 | B15: पुनस्त्रिविधा शरीरेन्द्रियविषयभेदात् । | C15: निर्देशः detailed enumeration of uddesha | E15: - | I15: योगः connecting
... A28: 26 | B28: उष्णस्पर्शवत्तेजः । | C28: पदार्थः Term definition | E28: - | I28: पदार्थः Term definition
A29: 27 | B29: तच्च द्विविधं नित्यमनित्यं च । | C29: निर्देशः detailed enumeration of uddesha | E29: - | F29: - | G29: - | H29: - | I29: योगः connecting
A30: 28 | B30: नित्यं परमाणुरूपं । | C30: उद्देशः concise summary | E30: - | F30: - | G30: - | H30: - | I30: पदार्थः Term definition
A31: 29 | B31: अनित्यं कार्यरूपं । | C31: उद्देशः concise summary | E31: - | F31: - | G31: - | H31: - | I31: पदार्थः Term definition
A32: 30 | B32: पुनस्त्रिविधं शरीरेन्द्रियविषयभेदात् । | C32: निर्देशः detailed enumeration of uddesha | E32: - | F32: - | G32: - | H32: - | I32: व्याख्यानम् explanation
A33: 31 | B33: शरीरमादित्यलोके प्रसिद्धम् । | C33: व्याख्यानम् explanation | E33: - | F33: - | G33: - | H33: - | I33: व्याख्यानम् explanation
A34: 32 | B34: इन्द्रियं रूपग्राहकं चक्षुः कृष्णताराग्रवर्ति । | C34: उद्देशः concise summary | E34: - | F34: - | G34: - | H34: - | I34: पदार्थः Term definition
A35: 33 | B35: विषयश्चतुर्विधः भौमदिव्यौदर्याकरज भेदात् । | C35: निर्देशः detailed enumeration of uddesha | E35: - | F35: - | G35: - | H35: - | I35: योगः connecting
A36: 34 | B36: भौमं वह्न्यादिकम् । | C36: उद्देशः concise summary | E36: - | F36: - | G36: - | H36: - | I36: पदार्थः Term definition
A37: 35 | B37: अबिन्धनं दिव्यं विद्युदादि । | C37: उद्देशः concise summary | E37: - | F37: - | G37: - | H37: - | I37: निदर्शनम्/दृष्टान्तः example
A38: 36 | B38: भुक्तस्य परिणामहेतुरौदर्यम् । | C38: उद्देशः concise summary | E38: - | F38: - | G38: - | H38: - | I38: पदार्थः Term definition
A39: 37 | B39: आकरजं सुवर्णादि ॥ ११॥ | C39: उद्देशः concise summary | E39: - | F39: - | G39: - | H39: - | I39: निदर्शनम्/दृष्टान्तः example
A40: 38 | B40: रूपरहीतः स्पर्शवान्वायुः । | C40: पदार्थः Term definition | F40: - | G40: - | H40: - | I40: पदार्थः Term definition
A41: 39 | B41: स द्विविधः नित्योऽनित्यश्च । | C41: निर्देशः detailed enumeration of uddesha | E41: - | F41: - | G41: - | H41: - | I41: योगः connecting
A42: 40 | B42: नित्यः परमाणुरूपः । | C42: उद्देशः concise summary | E42: - | F42: - | G42: - | H42: - | I42: व्याख्यानम् explanation
A43: 41 | B43: अनित्यः कार्यरूपः । | C43: उद्देशः concise summary | E43: - | F43: - | G43: - | H43: - | I43: व्याख्यानम् explanation
A44: 42 | B44: पुनस्त्रिविधः शरीरेन्द्रियविषयभेदात् ।. | C44: निर्देशः detailed enumeration of uddesha | E44: - | F44: - | G44: - | H44: - | I44: व्याख्यानम् explanation
A45: 43 | B45: शरीरं वायुलोके । | C45: व्याख्यानम् explanation | E45: - | F45: - | G45: - | H45: - | I45: व्याख्यानम् explanation
A46: 44 | B46: इन्द्रियं स्पर्शग्राहकं त्वक्सर्वशरीरवर्ति । | C46: उद्देशः concise summary | E46: - | F46: - | G46: - | H46: - | I46: व्याख्यानम् explanation
A47: 45 | B47: विषयो वृक्षादिकम्पनहेतुः ॥ १२॥ | C47: निदर्शनम्/दृष्टान्तः example | I47: व्याख्यानम् explanation
A48: 46 | B48: शरीरान्तःसंचारी वायुः प्राणः । | C48: पदार्थः Term definition | I48: पदार्थः Term definition
A49: 47 | B49: स च एकोऽप्युपाधिभेदात्प्राणापानादिसंज्ञां लभते ॥ १३॥ | C49: व्याख्यानम् explanation | I49: व्याख्यानम् explanation
A50: 48 | B50: शब्दगुणकमाकाशम् । | C50: पदार्थः Term definition | I50: पदार्थः Term definition
A51: 49 | B51: तच्चैकं विभु नित्यञ्च ॥ १४॥ | C51: उद्देशः concise summary | I51: समुच्चयः connection
A52: 50 | B52: अतीतादिव्यवहारहेतुः कालः । | C52: पदार्थः Term definition | I52: अधिकरणम् Topic
...

Sheet Sambandhas
A1: Source_vakya_id | B1: Vakya वाक्यम् | C1: Source_phrase | D1: Target_vakya_id | E1: Target_phrase | F1: Tantrayukti वाक्ययोः-स्तरे (तन्त्रयुक्तिः) | G1: Topic_tag अधिकरण-स्तरे | H1: Commentary_tag व्याख्यान-स्तरे | I1: Gist_tag तात्पर्य-स्तरे | J1: Concept_tag विषय-स्तरे | K1: Treatise_tag ग्रन्थ-स्तरे (अनुबन्ध-चतुष्टयम्) | L1: Relation_tag पदार्थ-संबन्धः | M1: Notes | Y1: तर्कसंग्रह मूल प्रश्नाः
A2: 0 | B2: निधाय हृदि विश्वेशं विधाय गुरुवन्दनम् । बालानां सुखबोधाय क्रियते तर्कसंग्रहः ॥
A3: 1 | B3: द्रव्यगुणकर्मसामान्यविशेषसमवायाऽभावाः सप्तपदार्थाः ॥ १॥ | C3: सप्तपदार्थ | D3: 0 | E3: तर्कसंग्रह | L3: प्रतिपाद्य - प्रतिपादक-भावः
A4: 1 | C4: पदार्थ | D4: 1 | E4: द्रव्य | L4: सामान्य-विशेष-भावः (Type-subtype)
A5: 1 | C5: पदार्थ | D5: 1 | E5: गुण | L5: सामान्य-विशेष-भावः (Type-subtype)
A6: 1 | C6: पदार्थ | D6: 1 | E6: कर्म | L6: सामान्य-विशेष-भावः (Type-subtype)
A7: 1 | C7: पदार्थ | D7: 1 | E7: सामान्य | L7: सामान्य-विशेष-भावः (Type-subtype)
A8: 1 | C8: पदार्थ | D8: 1 | E8: विशेष | L8: सामान्य-विशेष-भावः (Type-subtype)
A9: 1 | C9: पदार्थ | D9: 1 | E9: समवाय | L9: सामान्य-विशेष-भावः (Type-subtype)
A10: 1 | C10: पदार्थ | D10: 1 | E10: अभाव | L10: सामान्य-विशेष-भावः (Type-subtype)
A11: 1 | C11: द्रव्य | D11: 2 | E11: पृथिवी | L11: सामान्य-विशेष-भावः (Type-subtype)
A12: 1 | C12: द्रव्य | D12: 2 | E12: अप् | L12: सामान्य-विशेष-भावः (Type-subtype)
A13: 1 | C13: द्रव्य | D13: 2 | E13: तेजस् | L13: सामान्य-विशेष-भावः (Type-subtype)
A14: 1 | C14: द्रव्य | D14: 2 | E14: वायु | L14: सामान्य-विशेष-भावः (Type-subtype)
A15: 1 | C15: द्रव्य | D15: 2 | E15: आकाश | L15: सामान्य-विशेष-भावः (Type-subtype)
... A49: 1 | C49: कर्म | D49: 4 | E49: गमन | L49: सामान्य-विशेष-भावः (Type-subtype)
A50: 1 | C50: सामान्य | D50: 5 | E50: पर | L50: सामान्य-विशेष-भावः (Type-subtype) | Y50: अ-पृथिवी
A51: 1 | C51: सामान्य | D51: 5 | E51: अपर | L51: सामान्य-विशेष-भावः (Type-subtype)
A52: 1 | C52: सामान्य | D52: 313 | E52: नित्यमेकमनेकानुगतं | F52: पदार्थः Term definition | H52: - | L52: लक्ष्य - लक्षण-भावः Term - Definition
A53: 1 | C53: समवाय | D53: 318 | E53: नित्यसम्बन्धः | F53: पदार्थः Term definition | H53: - | L53: लक्ष्य - लक्षण-भावः Term - Definition | Y53: इ- जलम्‌
A54: 1 | C54: अभाव | D54: 8 | E54: प्रागभाव | L54: सामान्य-विशेष-भावः (Type-subtype) | Y54: ई- आकाशः
A55: 1 | C55: अभाव | D55: 8 | E55: प्रध्वंसाभाव | L55: सामान्य-विशेष-भावः (Type-subtype)
A56: 1 | C56: अभाव | D56: 8 | E56: अत्यन्ताभाव | L56: सामान्य-विशेष-भावः (Type-subtype)
A57: 1 | C57: अभाव | D57: 8 | E57: अन्योन्याभाव | L57: सामान्य-विशेष-भावः (Type-subtype)
A58: 2 | B58: तत्र द्रव्याणि पृथिव्यप्तेजोवाय्वाकाशाकालदिगात्ममनांसि नवैव ॥ २॥ | C58: तत्र | D58: 1 | E58: सप्तपदार्थ | L58: परामर्शक-परामृश्य-भावः (सर्वनाम) referent - referred
A59: 2 | C59: पृथिवी | D59: 9 | E59: गन्धवती | L59: लक्ष्य - लक्षण-भावः Term - Definition
A60: 2 | C60: पृथिवी | D60: 81 | E60: अन्यत्र | L60: प्रतियोगि - अनुयोगि-भावः
A61: 2 | C61: पृथिवी | D61: 13 | E61: शरीर | L61: सामान्य-विशेष-भावः (Type-subtype)
A62: 2 | C62: पृथिवी | D62: 13 | E62: इन्द्रिय | L62: सामान्य-विशेष-भावः (Type-subtype)
A63: 2 | C63: पृथिवी | D63: 13 | E63: विषय | L63: सामान्य-विशेष-भावः (Type-subtype)
A64: 2 | C64: अप् | D64: 18 | E64: शीतस्पर्शवत्यः | L64: लक्ष्य - लक्षण-भावः Term - Definition
A65: 2 | C65: अप् | D65: 22 | E65: शरीर | L65: सामान्य-विशेष-भावः (Type-subtype)
A66: 2 | C66: अप् | D66: 22 | E66: इन्द्रिय | L66: सामान्य-विशेष-भावः (Type-subtype)
A67: 2 | C67: अप् | D67: 22 | E67: विषय | L67: सामान्य-विशेष-भावः (Type-subtype)
A68: 2 | C68: तेजस् | D68: 26 | E68: उष्णस्पर्शवत् | L68: लक्ष्य - लक्षण-भावः Term - Definition | Y68: ३)मनः कीदृशं द्रव्यं ?
A69: 2 | C69: तेजस् | D69: 30 | E69: शरीर | L69: सामान्य-विशेष-भावः (Type-subtype)
A70: 2 | C70: तेजस् | D70: 30 | E70: इन्द्रिय | L70: सामान्य-विशेष-भावः (Type-subtype)
A71: 2 | C71: तेजस् | D71: 30 | E71: विषय | L71: सामान्य-विशेष-भावः (Type-subtype)
A72: 2 | C72: वायु | D72: 38 | E72: रूपरहीतः स्पर्शवान् | L72: लक्ष्य - लक्षण-भावः Term - Definition
A73: 2 | C73: वायु | D73: 42 | E73: शरीर | L73: सामान्य-विशेष-भावः (Type-subtype)
...

Sheet सूर्यः प्रत्यक्षदेवता
A1: Source_vakya_id | B1: Vakya वाक्यम् | C1: Source_phrase | D1: Target_vakya_id | E1: Target_phrase | G1: Topic_tag अधिकरण-स्तरे | H1: Commentary_tag व्याख्यान-स्तरे | I1: Gist_tag तात्पर्य-स्तरे | J1: Concept_tag विषय-स्तरे | K1: Treatise_tag ग्रन्थ-स्तरे (अनुबन्ध-चतुष्टयम्) | L1: Relation_tag | M1: Notes | Y1: तर्कसंग्रह मूल प्रश्नाः
A2: 1 | B2: पश्य, पूर्वस्यां दिशि सूर्य उदयते | C2: दिशि
A3: 1 | C3: पूर्वस्याम् | D3: 1 | E3: दिशि | L3: विशेषण - विशेष्य-भावः attribute - object
A4: 1 | C4: सूर्यः | D4: 1 | E4: पूर्वस्याम् | L4: कालिकः
A5: 1 | C5: उदयते | D5: 1 | E5: सूर्यः | L5: आधार - आधेय-भावः
A6: 2 | B6: तस्य प्रकाशः संप्रति रक्तः कोमलश्च वर्तते | C6: तस्य | D6: 1 | E6: सूर्यः | L6: परामर्शक-परामृश्य-भावः (सर्वनाम) referent - referred
A7: 2 | C7: प्रारकाशः | D7: `1 | E7: सूर्यः | L7: गुण-गुणि-भावः
A8: 2 | C8: रक्तः | E8: प्रारकाशः | L8: विशेषण - विशेष्य-भावः attribute - object
A9: 2 | C9: कोमलः | E9: प्रारकाशः | L9: विशेषण - विशेष्य-भावः attribute - object
A10: 3 | B10: सूर्यः उदयमानोऽन्धकारं नाशयति | C10: उदयमानः | D10: 1 | E10: सूर्यः | L10: विशेषण - विशेष्य-भावः attribute - object
C11: अन्धकारं नाशयति | D11: 1 | E11: सूर्यः | L11: कार्य - कारण-भावः effect - cause
A12: 4 | B12: प्राणिनः प्रबोधयति, कुसुमानि च विकासयति | C12: प्राणिनः प्रबोधयति | D12: 1 | E12: सूर्यः | L12: नियाम्य - नियामक-भावः
C13: कुसुमानि च विकासयति | D13: 1 | E13: सूर्यः | L13: नियाम्य - नियामक-भावः
A14: 5 | B14: सन्तो बालाः सूर्योदयात् पूर्वम् उषसि प्रबुध्य स्वीयान् पाठान् पठन्ति | C14: पाठान् | D14: 5 | E14: पठन्ति | L14: विषय - विषयि-भावः
C15: सूर्योदयात् पूर्वम् उषसि | E15: पाठान् पठन्ति | L15: प्रयोज्य - प्रयोजक-भावः
C16: पाठान् पठन्ति
A17: 6 | B17: यदा सूर्यः क्रमेणोद्गच्छन् नमसो मध्यमारोहति तदा ' मध्याह्नः' | C17: मध्याहः | D17: 6 | E17: यदा सूर्यः क्रमेणोद्गच्छन् नमसो मध्यमारोहति | L17: लक्ष्य - लक्षण-भावः Term - Definition
C18: सूर्यः क्रमेणोद्गच्छन् नमसो मध्यमारोहति
A19: 7 | B19: मध्याह्वात् पूर्वो भागः 'पूर्वाह्नः,' अपरो भागः 'अपराह्नः | C19: पूर्वाहः | E19: मध्याह्वात् पूर्वो भागः | L19: लक्ष्य - लक्षण-भावः Term - Definition
C20: मध्याह्वात् पूर्वो भागः
C21: अपराह्नः | E21: अपरो भागः | L21: लक्ष्य - लक्षण-भावः Term - Definition
A22: 8 | B22: मध्याह्ने सूर्यस्य प्रकाशः कठोरो भवति | C22: कठोरो
A23: 9 | B23: अपराहे सूर्यः क्रमेण पश्चिमां दिशमवतरति, तस्याम् अस्तं च गच्छति | C23: अस्तं च गच्छति
C24: अपराहे सूर्यः क्रमेण पश्चिमां दिशमवतरति
A25: 10 | B25: अस्तमये भूयोऽपि तस्य प्रकाशो रक्तः कोमलश्च मवति | C25: कोमलश्च | Y25: १) रूपरहित स्पर्शवत्‌ द्रव्यं किं?
C26: अस्तमये
A27: 11 | B27: सूर्यस्य भासा सर्वा सृष्टिः प्रकाशते | C27: भासा
C28: सृष्टिः प्रकाशते
A29: 12 | B29: सूर्येण तुल्यो नान्यस्तेजस्वी वर्तते | Y29: अ-पृथिवी
A30: 13 | B30: सूर्यः प्रत्यक्षदेवता | C30: सूर्यः | Y30: आ- वायुः
C31: प्रत्यक्षदेवता
A32: 14 | B32: सूर्योपासनया जनाः अरोगाः भवन्ति | C32: अरोगाः भवन्ति | Y32: इ- जलम्‌
C33: सूर्योपासनया
A34: 15 | B34: आरोग्यं भास्करात् इच्छेत् । इति हि महतां वचनम् | Y34: ई- आकाशः
A35: 16 | B35: सः देवैः असुरैश्च नमस्कृतः | C35: नमस्कृतः
A36: 17 | B36: तथा च श्रीमद्वाल्मीकिरामायणे आदित्यहृदयस्तोत्रम्
A37: 18 | B37: रश्मिमन्तं समुद्यन्तं देवासुरनमस्कृतम् । | C37: रश्मिमन्तं
C38: समुद्यन्तं
C39: देवासुरनमस्कृतम्
A40: 19 | B40: पूजयस्व विवस्वन्तं भास्करं भुवनेश्वरम् ॥ | C40: भास्करं
...

Sheet Tantrayukti
A1: अर्थशास्त्रम् | B1: चरकसंहिता | C1: चरकन्यासः | D1: सुश्रुतसंहिता | E1: विष्णुधर्मोत्तरपुराणम् | F1: Consolidated | G1: English meaning | H1: Notes | I1: लक्षणम् | J1: Explanation | K1: उदाहरणम्
F2: -
A3: अतिक्रान्तावेक्षणम् | B3: अतीतावेक्षा | C3: अतीतावेक्षा | D3: अतिक्रान्तावेक्षणम् | E3: अतिक्रान्तावेक्षणम् | F3: अतिक्रान्तावेक्षणम् | G3: retrospection | H3: अतिक्रान्तावेक्षणम् and अतीतावेक्षा are synonyms. | I3: पुरस्तादेवं विहितमिति कथनम् | J3: To say that it has been stated previously | K3: अवहितं हि चित्तमर्थान् पश्यति इत्युक्तं प्राक्
A4: अतिदेशः | B4: अतिदेशः | C4: अतिदेशः | D4: अतिदेशः | E4: अतिदेशः | F4: अतिदेशः | G4: retrospection | H4: - | I4: अतिदेशस्तु यत् किञ्चिदर्थजातम् उदीर्य च एवमन्यत्रापि ज्ञेयमिति स्थापनम् उक्तिभिः। | J4: To point out the connection between/among the allied or interrelated topics. | K4: दत्तस्य अप्रदानम् ऋणदानेन व्याख्यातम् | एवमन्यदपि व्याख्यातम्। एवमन्यदपि ज्ञेयम्।
A5: अधिकरणम् | B5: अधिकरणम् | C5: अधिकरणम् | D5: अधिकरणम् | E5: अधिकरणम् | F5: अधिकरणम् | G5: retrospection | H5: - | I5: यम् अर्थमधिकृत्य उच्यते तत् | J5: The subject-matter of discussion or consideration. | K5: पृथिव्या लाभे पालने च यावन्ति अर्थशास्त्राणि पूर्वाचार्यैः प्रस्थापितानि संहृत्य एकमिदम् अर्थशास्त्रं कृतम् (अर्थशास्त्रे)
A6: अनागतावेक्षणम् | B6: अनागतावेक्षा | C6: अनागतावेक्षा | D6: अनागतावेक्षणम् | E6: अनागतावेक्षणम् | F6: अनागतावेक्षणम् | G6: forward reference | H6: अनागतावेक्षणम् and अनागतावेक्षा are synonyms. | I6: पश्चादेवं विहितम् इति कथनम् | J6: The statement to the effect that it will be stated later at the appropriate place. | K6: तुलाप्रतिमानं पौतव्याध्यक्षे वक्ष्यामः।
A7: अनुमतम् | B7: अनुमतम् | C7: अनुमतम् | D7: अनुमतम् | E7: अनुमतम् | F7: अनुमतम् | G7: agreement | H7: - | I7: परमतम् अप्रतिषिद्धम् | J7: To give assent to or to approve of the view/s of the others | K7: तृषिमृषिकृषेः काश्यपस्य (अष्टाध्यायी) पक्षावुरस्यं प्रतिग्रह इत्यौशनसो व्यूहविभागः। (अर्थशास्त्रम्)
A8: अपदेशः | B8: अपदेशः | C8: अपदेशः | D8: अपदेशः | E8: अपदेशः | F8: अपदेशः/हेत्वर्थः | G8: reason | H8: According to Arthashastra, अपदेश is to quote another author's opinion on a given subject to refute it. This meaning can be included in उद्धार, hence this meaning has not been taken here. | I8: प्रतिज्ञातार्थसाधनाय हेतुवचनम् | J8: The statement of a reason or the statement of a cause of something | K8: मधुरेण श्लेष्म अभिवर्धते इति सुश्रुते।
A9: अपवर्गः | B9: अपवर्गः | C9: अपवर्गः | D9: अपवर्गः | E9: अपवर्गः | F9: अपवर्गः | G9: exception | H9: - | I9: अभिव्याप्य अपकर्षणम् अपवर्गः (कञ्चित् विधिम् उत्सर्गेण अभितः व्यापकं कृत्वा व्याप्यत्वेन अनिष्टात् विषयात् अपोहनम्) | J9: The statement of an exception to a general rule. | K9: अस्वेद्या विषोपसृष्टाः, अन्यत्र कीटविषात् इति।
A10: अर्थापत्तिः | B10: अर्थापत्तिः | C10: अर्थापत्तिः | D10: अर्थापत्तिः | E10: अर्थापत्तिः | F10: अर्थापत्तिः | G10: implied meaning | H10: - | I10: यदनुक्तमर्थात् आपद्यते | J10: The implied meaning is conveyed by the force of the meaning of the words used. | K10: ओदनं बुभुक्षुः इत्युक्ते अर्थादापन्नं भवति नायं पिपासुः यवागूमिति।
A11: उत्तरपक्षः | F11: उत्तरपक्षः | G11: Refutation | I11: तस्य निर्णयवाक्यम् | J11: Which refutes the पूर्वपक्ष | K11: प्रधानप्रत्ययार्थवचनमर्थस्यान्यप्रमाणत्वात्
A12: उद्देशः | B12: उद्देशः | C12: उद्देशः | D12: उद्देशः | E12: उद्देशः | F12: उद्देशः | G12: concise summary | H12: - | I12: समासवाक्यम् (सांक्षिप्तवाक्यम्) | J12: A brief mention of the topic to be discussed. | K12: विद्याविनयहेतुः इन्द्रियजयः
A13: उपदेशः | B13: उपदेशः | C13: उपदेशः | D13: उपदेशः | E13: उपदेशः | F13: उपदेशः | G13: advisory guidance | H13: उपदेशः एकान्तः नियोगः एषाम् अर्थसाम्यात् भ्रमसम्भवः स्यात्। अतः यत्र विधिरूपेण (विधिलिङ्, कृत्यप्रत्ययाः इत्यादि) उच्यते सः उपदेशः। विधिरूपेण उच्यते अवधारणवाचकः शब्दः च वर्तते चेत् नियोगः। यथा पथ्यमेव भोक्तव्यम्। अत्र विधिः अवगम्यते भोक्तव्यम् इत्यनेन, एव इति अवधारणार्थकः शब्दः अपि अस्ति। यत्र विधिः नास्ति अवधारणार्थकः शब्दः अस्ति सः एकान्तः। तद्यथा वाचामेव प्रसादेन लोकयात्रा प्रवर्तते। अथवा यस्य अपवादः नास्ति सः एकान्तः यथा व्याकरणे नित्यं हस्ते पाणावुपयमने इत्यादि। | I13: एवं वर्तितव्यम् इति | J13: A recommendatory advice in the form 'Do it like this' | K13: शास्त्रतः हि ज्ञात्वा दोषान् जह्यात् गुणालङ्कारान् च आददीत
A14: उपमानम् | F14: उपमानम् | G14: analogy | H14: - | I14: दृष्टेन अदृष्टार्थस्य साधनम् | J14: To prove the unknown or less known with known or with an analogy. | K14: यथा शिखा मयूराणां नागानां मणयो यथा। तद्वद् वेदाङ्गशास्त्राणां गणितं मूर्धनि स्थितम्॥
A15: ऊह्यम् | B15: ऊह्यम् | C15: ऊह्यम् | D15: ऊह्यम् | E15: ऊह्यम् | F15: ऊह्यम् | G15: deduction | H15: - | I15: यदनिर्दिष्टं बुद्द्या अवगम्यते | J15: To infer by reasoning what the author has not explicitly expressed. | K15: अनेनैव पथान्यच्च समानन्यायमूह्यताम्। दिङ्मात्रं दर्शितं धीरैः अनुक्तमनुमीयताम्।
A16: एकान्तः | B16: एकान्तः | C16: एकान्तः | D16: एकान्तः | E16: एकान्तः | F16: एकान्तः | G16: exclusive statement | H16: see उपदेशः | I16: सर्वत्र यदवधारणेन उच्यते (यस्य अपवादः नास्ति) | J16: A rule which has no exception; an expression which yields one and only one meaning. | K16: तस्मात् उत्थानमात्मनः कुर्वीत
A17: निदर्शनम् | B17: निदर्शनम् | C17: निदर्शनम् | D17: निदर्शनम् | F17: निदर्शनम्/दृष्टान्तः | G17: example | H17: दृष्टान्तः अत्रैव योजयितुं शक्यते। दृष्टान्त can be merged with this. | I17: दृष्टान्तः | J17: An example cited to clarify or prove a scientific topic. | K17: तदल्पमपि नोपेक्ष्यं काव्यं दुष्टं कथञ्चन। स्यात् वपुः सुन्दरमपि श्वित्रेणैकेन दुर्भगम्॥
A18: नियोगः | B18: संनियोगः | C18: संनियोगः | D18: नियोगः | E18: नियोगः | F18: नियोगः | G18: Dictate | H18: see उपदेशः | I18: इदमेव कर्तव्यम् इति कथनम् | J18: A command or a dictate that should be always be carried out. | K18: इति दोषाः दशैवेते वर्ज्याः काव्येषु सूरिभिः।
A19: - | B19: निर्णयः | C19: निर्णयः | D19: निर्णयः | E19: निर्णयः | F19: निर्णयः | G19: conclusion | H19: - | I19: विचारितस्य अर्थस्य व्यवस्थापनम् (उत्तरपक्षः अत्र योजयितुं शक्यते) | J19: A determined view or conclusion
A20: निर्देशः | B20: निर्देशः | C20: निर्देशः | D20: निर्देशः | E20: निर्देशः | F20: निर्देशः | G20: detailed enumeration of uddesha | H20: - | I20: विस्तरवचनम् | J20: A detailed enumeration of the previously briefly mentioned topics in the same order. | K20: कर्णत्वगक्षिजिह्वाघ्राणेन्द्रियाणां शब्दस्पर्शरूपरसगन्धेष्वप्रतिपत्तिः इन्द्रियजयः
A21: निर्वचनम् | B21: निर्वचनम् | C21: निर्वचनम् | D21: निर्वचनम् | E21: निर्वचनम् | F21: निर्वचनम् | G21: etymology | H21: - | I21: शब्दनिष्पत्तिः | J21: Etymological interpretation of a scientific term. | K21: अनु पश्चात् आस उपक्षेपः प्रयोगः अनुप्रासः । व्यसति एनं श्रेयसः इति व्यसनम्।
A22: पदार्थः | B22: पदार्थः | C22: पदार्थः | D22: पदार्थः | E22: पदार्थः | F22: पदार्थः | G22: Term definition | H22: - | I22: पदार्थः नाम पदस्य पदयोः पदानां वा अर्थः | J22: The meaning of a word. | K22: यः पितृपैतामहम् अर्थम् अन्यायेन भक्षयति स मूलहरः
A23: पूर्वपक्षः | B23: पूर्वपक्षः | C23: पूर्वपक्षः | D23: पूर्वपक्षः | E23: पूर्वपक्षः | F23: पूर्वपक्षः | G23: prima facie argument | H23: - | I23: प्रतिषेद्धव्यं वाक्यम् | J23: A statement which needs to be refuted.
A24: प्रदेशः | B24: प्रदेशः | C24: प्रदेशः | D24: प्रदेशः | E24: प्रदेशः | F24: प्रदेशः | G24: partial mention to prove | H24: In अतिक्रान्तावेक्षण and अनागतावेक्षण, there is a reference to the past statement or future statement, but neither of these concerns itself with proving anything. | I24: वक्तव्येन साधनम् | J24: To prove the present subject with something that was stated/something to be stated later. | K24: सामदाानभेददण्डैर्वा यथापत्सु व्याख्यास्यामः।
A25: प्रसङ्गः | B25: प्रसङ्गः | C25: प्रसङ्गः | D25: प्रसङ्गः | E25: प्रसङ्गः | F25: प्रसङ्गः | G25: Repetition | H25: - | I25: पूर्वाभिहितस्य अर्थस्य केनचित् सम्बन्धान्तरेण पुनरभिधानम् | J25: To state or describe again, what has been stated or described earlier, in a different connction. | K25: कृषिकर्मप्रदिष्टायां भूमौ इति समानं पूर्वेण।
A26: योगः | B26: योगः | C26: योगः | D26: योगः | E26: योगः | F26: योगः | G26: connecting with a previous sentence | H26: पदानाम् अन्वयकरणम् अपि योगः भवति। | I26: वाक्ययोजना | J26: Mutual organiation of the meanings of two sentences./ To join the words together to obtain a meaningful sentence.
A27: वाक्यशेषः | B27: वाक्यशेषः | C27: वाक्यशेषः | D27: वाक्यशेषः | E27: वाक्यशेषः | F27: वाक्यशेषः | G27: filling implied words | H27: - | I27: येन पदेन अनुक्तेन वाक्यं समाप्यते | J27: To provide the unsaid word/s in order to complete the construction or the meaning of a sentence. | K27: ‘छिन्नपक्षस्येव राज्ञश्चेष्टानाशश्चेति’ तत्र शकुनेः इति वाक्यशेषः। यथा वा सुश्रुते शिरःपाणिपादपार्श्वपृष्ठोदरोरसाम् इत्युक्ते पुरुषग्रहणमिति गम्यते।
A28: विकल्पः | B28: विकल्पनम् | C28: विकल्पनम् | D28: विकल्पः | E28: विकल्पः | F28: विकल्पः | G28: alternative | H28: विकल्पनं विकल्पः are synonyms. | I28: अनेेन वा अनेन वा इति | J28: To state an alternative | K28: सारोदकं वा अथ कुशोदकं वा
A29: विधानम् | B29: विधानम् | C29: विधानम् | D29: विधानम् | E29: विधानम् | F29: विधानम् | G29: table of content | H29: - | I29: शास्त्रस्य प्रकरणानुपूर्वी | J29: The table of contents of a scientific work | K29: विद्यासमुद्देशे वृद्धसंयोगः इन्द्रियजयः इत्यादि
A30: विपर्ययः | B30: विपर्ययः | C30: विपर्ययः | D30: विपर्ययः | E30: विपर्ययः | F30: विपर्ययः | G30: contrariety | H30: - | I30: प्रतिलोमेन साधनम् | J30: To prove a topic by means of the opposite meaning | K30: विपरीतमतुष्टस्य। इति वैदर्भमार्गस्य प्राणा दशगुणा मताः। एषां विपर्ययः प्रायः दृश्यते गौडवर्मनि।
A31: व्याख्यानम् | B31: व्याख्यानम् | C31: व्याख्यानम् | D31: व्याख्यानम् | F31: व्याख्यानम् | G31: explanation | H31: - | I31: अतिशयवर्णना | J31: A detaled explanation of all the aspects of a topic.
A32: समुच्चयः | B32: समुच्चयः | C32: समुच्चयः | D32: समुच्चयः | E32: समुच्चयः | F32: समुच्चयः | G32: connection | H32: - | I32: अनेन च अनेन च इति | J32: A combination or assemblage generally denoted by च | K32: वर्णश्च स्वरश्च
A33: संशयः | B33: संशयः | C33: संशयः | D33: संशयः | E33: संशयः | F33: संशयः | G33: Doubt | H33: It is different from विकल्पः. In विकल्प author suggests various alternatives whereas in संशयः the author suggests ways and means of removing a doubt. | I33: उभयहेतुदर्शनम् | J33: Doubt or indecision | K33: इतः च्युताः पुनः भविष्यामः न वा इति संशयः। कस्मात्? सन्ति ह्येके प्रत्यक्षपराः परोक्षत्वात् पुनर्भवस्य नास्तिक्यमाश्रिताः। सन्ति चापरे आगमप्रत्ययादेव पुनर्भवमिच्छन्तीति।
A34: स्वसंज्ञा | B34: स्वसंज्ञा | C34: स्वसंज्ञा | D34: स्वसंज्ञा | E34: स्वसंज्ञा | F34: स्वसंज्ञा | G34: technical term | H34: Difference between पदार्थ and स्वसंज्ञा is, the पदार्थ is concerned with the meaning of a word whereas the स्वसंज्ञा is concerned with the word itself. | I34: अन्यशास्त्रासामान्या | J34: A technical term | K34: काव्य अलङ्कार अकवि etc are the स्वसंज्ञs of अलङ्कारशास्त्र
A35: हेत्वर्थः | B35: हेत्वर्थः | C35: हेत्वर्थः | D35: हेत्वर्थः | E35: हेत्वर्थः | H35: अपदेश and हेत्वर्थ make a statement of a cause and effect. There is no much difference between the two. | I35: - | J35: - | K35: -
B36: उद्धारः | C36: उद्धारः | F36: उद्धारः | G36: Opponent's view | H36: - | I36: परपक्षदूषणं कृत्वा स्वपक्षोद्धरणम् | J36: To point out flaws in other's views and to raise one's viewpoints. | K36: मन्त्रिपरिषदं द्वादशामात्यान् कुर्वीतेति मानवाः, षोडेशे बार्हस्पत्याः
B37: नैकान्तः | C37: नैकान्तः | D37: अनेकान्तः | E37: अनेकान्तः | F37: नैकान्तः | G37: Inclusive statement | H37: नैकान्तः and अनेकान्तः are synonyms. | I37: यत् उच्यमानम् अपि अवश्यंभावित्वेन अनियतम् (सापवादं वाक्यम्) | J37: To make an inclusive statement, to state a rule which has exception. | K37: व्याकरणे ''आत् गुणः'' इत्यादिः।
B38: प्रत्युत्सारः | C38: प्रत्युत्सारः | H38: This can be merged in the उद्धार. Because it also includes refutation of sombody''s view.
B39: प्रयोजनम् | C39: प्रयोजनम् | F39: प्रयोजनम् | G39: purpose | H39: - | I39: यदर्थं कामयमानः प्रवर्तते | J39: The purpose of an action. | K39: सुजनावगमाय भामहेन ग्रथितं रक्रिलगोमिसूनुनेदम्।
B40: सम्भवः | C40: सम्भवः | F40: सम्भवः | G40: possibility | H40: - | I40: यत् यस्मिन् उपपद्यते सः तस्य सम्भवः | J40: A mention of that which is possible in a particluar situation. | K40: इह खलु द्वये कवयः सम्भवन्ति अरोचकिनः सतृणाभ्यवहारिणः च इति।
...
